Workbook

Sheet Read Me
A2: Objective | B2: To demonstrate practical Excel skills in data cleaning, validation, and documentation by transforming a raw employee dataset into a standardized, high-quality dataset ready for business use.
A3: Project Title | B3: Employee Master Data Cleaning and Validation Project
A4: Project Overview | B4: This project demonstrates the process of cleaning, validating, and standardizing an employee master dataset using Microsoft Excel. The goal is to improve data quality and prepare the dataset for reporting and analysis.
A5: Dataset Information
A6: Item | B6: Description
A7: Dataset | B7: Employee Master Data
A8: Total Records | B8: 1000
A9: Total Fields | B9: 10
A10: Software | B10: Microsoft Excel
A11: Data Validation Performed | B11: Employee ID uniqueness check
B12: Full Name formatting
B13: Gender validation
B14: Date of Birth validation
B15: Join Date validation
B16: Department validation
B17: Position validation
B18: Employment Status validation
B19: Email validation
B20: Phone Number validation
A21: Excel Functions Used | B21: IF
B22: COUNTIF
B23: EXACT
B24: PROPER
B25: TRIM
B26: LEFT
B27: RIGHT
B28: ISNUMBER
B29: FIND & REPLACE
B30: UPPER
B31: PivotTable
B32: FILTER
B33: SUBSTITUTE
B34: VLOOKUP
A35: Skills Demonstrated | B35: Microsoft Excel
B36: Data Cleaning
B37: Data Validation
B38: Data Quality Assessment
B39: Data Documentation
B40: Pivot Table
B41: Dashboard Design
...

Sheet Employee_Raw
A1: Employee Master Database Management
A2: No | B2: Employee ID | C2: Full Name | D2: Gender | E2: DOB | F2: Join Date | G2: Department | H2: Position | I2: Status | J2: Email | K2: Phone
A3: 1 | B3: EMP0001 | C3: Ridwan Akmaluddin | D3: Male | E3: 1988-05-25 | F3: 2025-11-03 | G3: Prodction | H3: operator | I3: Active | J3: ridwanakmaluddin@email.com | K3: 082188191195
A4: 2 | B4: EMP0002 | C4: siti maghfiroh | D4: female | E4: 1986-10-02 | F4: 2025-11-03 | G4: Production | H4: Production | I4: active | J4: sitimaghfiroh@email.com | K4: 893260231
A5: 3 | B5: EMP0003 | C5: diyah rhodhotul avivah | D5: Female | E5: 1994-10-02 | F5: 2025-11-03 | G5: QC | H5: QC Inspector | I5: resigned | J5: diyahrhodhotulavivah@imail.com | K5: 088550888361
A6: 4 | B6: EMP0004 | C6: Avielva Zhelviany | D6: Female | E6: 2003-05-04 | F6: 2025-11-03 | G6: purchasing | H6: Purchasing Staff | I6: Active | J6: avielvazhelviany@imail.com | K6: 085713227015
A7: 5 | B7: EMP0005 | C7: Dede Mulyaningsih | D7: female | E7: 1997-11-23 | F7: 2025-11-03 | G7: Prodction | H7: Operator | I7: Active | J7: dedemulyaningsih@imail.com | K7: 080015675393
A8: 6 | B8: EMP0006 | C8: ferri riyanto | D8: male | E8: 2002-06-16 | F8: 2025-11-03 | G8: Production | H8: operator | I8: Probation | J8: ferririyanto@imail.com | K8: 082274087008
A9: 7 | B9: EMP0007 | C9: alfi nur fadilah | D9: Female | E9: 1986-10-25 | F9: 2025-11-03 | G9: QC | H9: qc inspector | I9: Active | J9: alfinurfadilah@imail.com | K9: 083226933728
A10: 8 | B10: EMP0008 | C10: Latif Ainur Rokhmah | D10: Female | E10: 1988-10-05 | F10: 2025-11-03 | G10: purchasing | H10: Purchasing Staff | I10: ACTIVE | J10: latifainurrokhmah@email.com | K10: 087585339477
A11: 9 | B11: EMP0009 | C11: Fajar B Pratama | D11: Male | E11: 1993-10-27 | F11: 2025-11-03 | G11: production | H11: operator | I11: Probation | J11: fajarbpratama@imail.com | K11: 089883379308
A12: 10 | B12: EMP0010 | C12: Veby Astriani | D12: female | E12: 1988-03-14 | F12: 2025-11-03 | G12: Production | H12: operator | I12: resigned | J12: vebyastriani@email.com | K12: 085418191103
A13: 11 | B13: EMP0011 | C13: a khoirurroziqin | D13: male | E13: 1998-03-28 | F13: 2025-11-03 | G13: finance | H13: Finance Admin | I13: probation | J13: akhoirurroziqin@imail.com | K13: 085944301279
A14: 12 | B14: EMP0012 | C14: dian nur ardilla | D14: male | E14: 1998-11-02 | F14: 2025-11-03 | G14: Engineering | H14: Technician | I14: active | J14: diannurardilla@imail.com | K14: 803522114
A15: 13 | B15: EMP0013 | C15: lutfi ardiansyah | D15: male | E15: 2001-07-30 | F15: 2025-11-03 | G15: Production | H15: operator | I15: Probation | J15: lutfiardiansyah@email.com | K15: 87480756904
A16: 14 | B16: EMP0014 | C16: rahmayanti | D16: female | E16: 2003-10-12 | F16: 2025-11-03 | G16: Production | H16: operator | I16: active | J16: rahmayanti@email.com | K16: 084798489654
A17: 15 | B17: EMP0015 | C17: Rahma Yuliana | D17: female | E17: 1999-06-16 | F17: 2025-11-03 | G17: Production | H17: operator | I17: probation | J17: rahmayuliana@email.com | K17: 853887755
A18: 16 | B18: EMP0016 | C18: wawan setiawan wandi | D18: Male | E18: 2004-01-02 | F18: 2025-11-03 | G18: Warehouse | H18: warehouse staff | I18: probation | J18: wawansetiawanwandi@email.com | K18: 080556387310
A19: 17 | B19: EMP0017 | C19: nur aisyah | D19: female | E19: 1987-11-16 | F19: 2025-11-03 | G19: Finace | H19: Finance Admin | I19: Probation | J19: nuraisyah@email.com | K19: 085278436321
A20: 18 | B20: EMP0018 | C20: Muhammad Rifal Ilyas | D20: male | E20: 1986-04-13 | F20: 2025-11-03 | G20: it | H20: it support | I20: active | J20: muhammadrifalilyas@email.com | K20: 086137380821
A21: 19 | B21: EMP0019 | C21: Tiyo Aryo | D21: male | E21: 1999-07-15 | F21: 2025-11-03 | G21: Production | H21: operator | I21: probation | J21: tiyoaryo@email.com | K21: 085740892375
A22: 20 | B22: EMP0020 | C22: Aditya Nugraha | D22: Male | E22: 2000-07-25 | F22: 2025-11-03 | G22: marketing | H22: marketing staff | I22: active | J22: adityanugraha@imail.com | K22: 087056427531
A23: 21 | B23: EMP0021 | C23: abdul aziz | D23: male | E23: 1994-07-20 | F23: 2025-11-03 | G23: Engineering | H23: Technician | I23: ACTIVE | J23: abdulaziz@imail.com | K23: 081418040871
A24: 22 | B24: EMP0022 | C24: ozi priyanto | D24: male | E24: 1987-09-27 | F24: 2025-11-03 | G24: Production | H24: operator | I24: probation | J24: ozipriyanto@email.com | K24: 087596693717
A25: 23 | B25: EMP0023 | C25: M Aditya Mumin Ansori | D25: Male | E25: 1985-08-16 | F25: 2025-11-03 | G25: marketing | H25: marketing staff | I25: ACTIVE | J25: madityamuminansori@email.com | K25: 084236403700
A26: 24 | B26: EMP0024 | C26: Siti Rochanah | D26: Female | E26: 1985-06-30 | F26: 2025-11-03 | G26: production | H26: operator | I26: resigned | J26: sitirochanah@email.com | K26: 089977416966
A27: 25 | B27: EMP0025 | C27: miske nur agustina | D27: Male | E27: 1995-05-03 | F27: 2025-11-03 | G27: warehouse | H27: Warehouse Staff | I27: Resigned | J27: miskenuragustina@email.com | K27: 085419858274
A28: 26 | B28: EMP0026 | C28: Novi Wulandari | D28: female | E28: 1985-03-02 | F28: 2025-11-03 | G28: Prodction | H28: Operator | I28: probation | J28: noviwulandari@email.com | K28: 084291820015
A29: 27 | B29: EMP0027 | C29: rohmat | D29: male | E29: 1994-02-13 | F29: 2025-11-03 | G29: Production | H29: operator | I29: Probation | J29: rohmat@email.com | K29: 085701851280
... A39: 37 | B39: EMP0037 | C39: Rizqi Amalia | D39: Female | E39: 1989-11-04 | F39: 2025-11-03 | G39: production | H39: operator | I39: Resigned | J39: rizqiamalia@email.com | K39: 086508782132
A40: 38 | B40: EMP0038 | C40: Beni | D40: Male | E40: 2001-03-09 | F40: 2025-11-03 | G40: Prodction | H40: Operator | I40: ACTIVE | J40: beni@imail.com | K40: 846922616
A41: 39 | B41: EMP0039 | C41: Vitriya Amanda Putri | D41: female | E41: 2004-01-25 | F41: 2025-11-03 | G41: hr | H41: hr staff | I41: ACTIVE | J41: vitriyaamandaputri@email.com | K41: 086460584576
A42: 40 | B42: EMP0040 | C42: Alda Surya Wijaya | D42: Male | E42: 1988-01-26 | F42: 2025-11-03 | G42: production | H42: operator | I42: resigned | J42: aldasuryawijaya@imail.com | K42: 088873927718
A43: 41 | B43: EMP0041 | C43: Fika Suci Sanawaliyah | D43: female | E43: 1987-11-24 | F43: 2025-11-03 | G43: Production | H43: operator | I43: Probation | J43: fikasucisanawaliyah@imail.com | K43: 85636332286
A44: 42 | B44: EMP0042 | C44: Bagus Wiranto | D44: Male | E44: 1990-05-01 | F44: 2025-11-03 | G44: purchasing | H44: Purchasing Staff | I44: active | J44: baguswiranto@imail.com | K44: 082626918134
A45: 43 | B45: EMP0043 | C45: Sahrul Faizal Ramadhon | D45: Male | E45: 1990-01-10 | F45: 2025-11-03 | G45: Production | H45: operator | I45: Active | J45: sahrulfaizalramadhon@email.com | K45: 084739492257
A46: 44 | B46: EMP0044 | C46: Dian Prastiana | D46: male | E46: 1987-01-08 | F46: 2025-11-03 | G46: prodution | H46: operator | I46: Probation | J46: dianprastiana@imail.com | K46: 086451989393
A47: 45 | B47: EMP0045 | C47: Uswatun Khasanah | D47: Female | E47: 1989-12-22 | F47: 2025-11-03 | G47: production | H47: Operator | I47: active | J47: uswatunkhasanah@email.com | K47: 084176066224
A48: 46 | B48: EMP0046 | C48: Ika Risyifa Khaerunissa | D48: female | E48: 1996-10-18 | F48: 2025-11-03 | G48: Production | H48: operator | I48: active | J48: ikarisyifakhaerunissa@email.com | K48: 082084751572
A49: 47 | B49: EMP0047 | C49: Ayu Pratmawati | D49: Female | E49: 1993-10-06 | F49: 2025-11-03 | G49: production | H49: Operator | I49: probation | J49: ayupratmawati@imail.com | K49: 086743969318
...

Sheet Working Copy & Validation Check
A1: Employee Master Database Management | M1: Validation Check
A2: No | B2: Employee ID | C2: Full Name | D2: Gender | E2: DOB | F2: Join Date | G2: Department | H2: Position | I2: Status | J2: Email | K2: Phone | M2: Employee ID Check | N2: Full Name Check | O2: Gender Check | P2: DOB Check | Q2: Join Date Check | R2: Department Check | S2: Position Check | T2: Status Check | U2: Email Check | V2: Phone Check
A3: 1 | B3: EMP0001 | C3: Ridwan Akmaluddin | D3: Male | E3: 1988-05-25 | F3: 2025-11-03 | G3: Prodction | H3: operator | I3: Active | J3: ridwanakmaluddin@email.com | K3: 082188191195 | M3: =IF(COUNTIF($B$3:$B$1002,B3)>1,"Duplicate","Ok") -> Ok | N3: =EXACT(C3,PROPER(C3)) -> TRUE | O3: =EXACT(D3,PROPER(D3)) -> TRUE | P3: =IF(ISNUMBER(E3),"TRUE","FALSE") -> FALSE | Q3: =IF(ISNUMBER(F3),"TRUE","FALSE") -> FALSE | R3: =EXACT(G3,PROPER(G3)) -> TRUE | S3: =EXACT(H3,PROPER(H3)) -> FALSE | T3: =EXACT(I3,PROPER(I3)) -> TRUE | U3: =IF(RIGHT(J3,10)="@email.com","TRUE","FALSE") -> TRUE | V3: =IF(LEFT(K3,2)="08","TRUE","FALSE") -> TRUE
A4: 2 | B4: EMP0002 | C4: siti maghfiroh | D4: female | E4: 1986-10-02 | F4: 2025-11-03 | G4: Production | H4: Production | I4: active | J4: sitimaghfiroh@email.com | K4: 893260231 | M4: =IF(COUNTIF($B$3:$B$1002,B4)>1,"Duplicate","Ok") -> Ok | N4: =EXACT(C4,PROPER(C4)) -> FALSE | O4: =EXACT(D4,PROPER(D4)) -> FALSE | P4: =IF(ISNUMBER(E4),"TRUE","FALSE") -> FALSE | Q4: =IF(ISNUMBER(F4),"TRUE","FALSE") -> FALSE | R4: =EXACT(G4,PROPER(G4)) -> TRUE | S4: =EXACT(H4,PROPER(H4)) -> TRUE | T4: =EXACT(I4,PROPER(I4)) -> FALSE | U4: =IF(RIGHT(J4,10)="@email.com","TRUE","FALSE") -> TRUE | V4: =IF(LEFT(K4,2)="08","TRUE","FALSE") -> FALSE
A5: 3 | B5: EMP0003 | C5: diyah rhodhotul avivah | D5: Female | E5: 1994-10-02 | F5: 2025-11-03 | G5: QC | H5: QC Inspector | I5: resigned | J5: diyahrhodhotulavivah@imail.com | K5: 088550888361 | M5: =IF(COUNTIF($B$3:$B$1002,B5)>1,"Duplicate","Ok") -> Ok | N5: =EXACT(C5,PROPER(C5)) -> FALSE | O5: =EXACT(D5,PROPER(D5)) -> TRUE | P5: =IF(ISNUMBER(E5),"TRUE","FALSE") -> FALSE | Q5: =IF(ISNUMBER(F5),"TRUE","FALSE") -> FALSE | R5: =EXACT(G5,PROPER(G5)) -> FALSE | S5: =EXACT(H5,PROPER(H5)) -> FALSE | T5: =EXACT(I5,PROPER(I5)) -> FALSE | U5: =IF(RIGHT(J5,10)="@email.com","TRUE","FALSE") -> FALSE | V5: =IF(LEFT(K5,2)="08","TRUE","FALSE") -> TRUE
A6: 4 | B6: EMP0004 | C6: Avielva Zhelviany | D6: Female | E6: 2003-05-04 | F6: 2025-11-03 | G6: purchasing | H6: Purchasing Staff | I6: Active | J6: avielvazhelviany@imail.com | K6: 085713227015 | M6: =IF(COUNTIF($B$3:$B$1002,B6)>1,"Duplicate","Ok") -> Ok | N6: =EXACT(C6,PROPER(C6)) -> TRUE | O6: =EXACT(D6,PROPER(D6)) -> TRUE | P6: =IF(ISNUMBER(E6),"TRUE","FALSE") -> FALSE | Q6: =IF(ISNUMBER(F6),"TRUE","FALSE") -> FALSE | R6: =EXACT(G6,PROPER(G6)) -> FALSE | S6: =EXACT(H6,PROPER(H6)) -> TRUE | T6: =EXACT(I6,PROPER(I6)) -> TRUE | U6: =IF(RIGHT(J6,10)="@email.com","TRUE","FALSE") -> FALSE | V6: =IF(LEFT(K6,2)="08","TRUE","FALSE") -> TRUE
A7: 5 | B7: EMP0005 | C7: Dede Mulyaningsih | D7: female | E7: 1997-11-23 | F7: 2025-11-03 | G7: Prodction | H7: Operator | I7: Active | J7: dedemulyaningsih@imail.com | K7: 080015675393 | M7: =IF(COUNTIF($B$3:$B$1002,B7)>1,"Duplicate","Ok") -> Ok | N7: =EXACT(C7,PROPER(C7)) -> TRUE | O7: =EXACT(D7,PROPER(D7)) -> FALSE | P7: =IF(ISNUMBER(E7),"TRUE","FALSE") -> FALSE | Q7: =IF(ISNUMBER(F7),"TRUE","FALSE") -> FALSE | R7: =EXACT(G7,PROPER(G7)) -> TRUE | S7: =EXACT(H7,PROPER(H7)) -> TRUE | T7: =EXACT(I7,PROPER(I7)) -> TRUE | U7: =IF(RIGHT(J7,10)="@email.com","TRUE","FALSE") -> FALSE | V7: =IF(LEFT(K7,2)="08","TRUE","FALSE") -> TRUE
A8: 6 | B8: EMP0006 | C8: ferri riyanto | D8: male | E8: 2002-06-16 | F8: 2025-11-03 | G8: Production | H8: operator | I8: Probation | J8: ferririyanto@imail.com | K8: 082274087008 | M8: =IF(COUNTIF($B$3:$B$1002,B8)>1,"Duplicate","Ok") -> Ok | N8: =EXACT(C8,PROPER(C8)) -> FALSE | O8: =EXACT(D8,PROPER(D8)) -> FALSE | P8: =IF(ISNUMBER(E8),"TRUE","FALSE") -> FALSE | Q8: =IF(ISNUMBER(F8),"TRUE","FALSE") -> FALSE | R8: =EXACT(G8,PROPER(G8)) -> TRUE | S8: =EXACT(H8,PROPER(H8)) -> FALSE | T8: =EXACT(I8,PROPER(I8)) -> TRUE | U8: =IF(RIGHT(J8,10)="@email.com","TRUE","FALSE") -> FALSE | V8: =IF(LEFT(K8,2)="08","TRUE","FALSE") -> TRUE
A9: 7 | B9: EMP0007 | C9: alfi nur fadilah | D9: Female | E9: 1986-10-25 | F9: 2025-11-03 | G9: QC | H9: qc inspector | I9: Active | J9: alfinurfadilah@imail.com | K9: 083226933728 | M9: =IF(COUNTIF($B$3:$B$1002,B9)>1,"Duplicate","Ok") -> Ok | N9: =EXACT(C9,PROPER(C9)) -> FALSE | O9: =EXACT(D9,PROPER(D9)) -> TRUE | P9: =IF(ISNUMBER(E9),"TRUE","FALSE") -> FALSE | Q9: =IF(ISNUMBER(F9),"TRUE","FALSE") -> FALSE | R9: =EXACT(G9,PROPER(G9)) -> FALSE | S9: =EXACT(H9,PROPER(H9)) -> FALSE | T9: =EXACT(I9,PROPER(I9)) -> TRUE | U9: =IF(RIGHT(J9,10)="@email.com","TRUE","FALSE") -> FALSE | V9: =IF(LEFT(K9,2)="08","TRUE","FALSE") -> TRUE
A10: 8 | B10: EMP0008 | C10: Latif Ainur Rokhmah | D10: Female | E10: 1988-10-05 | F10: 2025-11-03 | G10: purchasing | H10: Purchasing Staff | I10: ACTIVE | J10: latifainurrokhmah@email.com | K10: 087585339477 | M10: =IF(COUNTIF($B$3:$B$1002,B10)>1,"Duplicate","Ok") -> Ok | N10: =EXACT(C10,PROPER(C10)) -> TRUE | O10: =EXACT(D10,PROPER(D10)) -> TRUE | P10: =IF(ISNUMBER(E10),"TRUE","FALSE") -> FALSE | Q10: =IF(ISNUMBER(F10),"TRUE","FALSE") -> FALSE | R10: =EXACT(G10,PROPER(G10)) -> FALSE | S10: =EXACT(H10,PROPER(H10)) -> TRUE | T10: =EXACT(I10,PROPER(I10)) -> FALSE | U10: =IF(RIGHT(J10,10)="@email.com","TRUE","FALSE") -> TRUE | V10: =IF(LEFT(K10,2)="08","TRUE","FALSE") -> TRUE
A11: 9 | B11: EMP0009 | C11: Fajar B Pratama | D11: Male | E11: 1993-10-27 | F11: 2025-11-03 | G11: production | H11: operator | I11: Probation | J11: fajarbpratama@imail.com | K11: 089883379308 | M11: =IF(COUNTIF($B$3:$B$1002,B11)>1,"Duplicate","Ok") -> Ok | N11: =EXACT(C11,PROPER(C11)) -> TRUE | O11: =EXACT(D11,PROPER(D11)) -> TRUE | P11: =IF(ISNUMBER(E11),"TRUE","FALSE") -> FALSE | Q11: =IF(ISNUMBER(F11),"TRUE","FALSE") -> FALSE | R11: =EXACT(G11,PROPER(G11)) -> FALSE | S11: =EXACT(H11,PROPER(H11)) -> FALSE | T11: =EXACT(I11,PROPER(I11)) -> TRUE | U11: =IF(RIGHT(J11,10)="@email.com","TRUE","FALSE") -> FALSE | V11: =IF(LEFT(K11,2)="08","TRUE","FALSE") -> TRUE
A12: 10 | B12: EMP0010 | C12: Veby Astriani | D12: female | E12: 1988-03-14 | F12: 2025-11-03 | G12: Production | H12: operator | I12: resigned | J12: vebyastriani@email.com | K12: 085418191103 | M12: =IF(COUNTIF($B$3:$B$1002,B12)>1,"Duplicate","Ok") -> Ok | N12: =EXACT(C12,PROPER(C12)) -> TRUE | O12: =EXACT(D12,PROPER(D12)) -> FALSE | P12: =IF(ISNUMBER(E12),"TRUE","FALSE") -> FALSE | Q12: =IF(ISNUMBER(F12),"TRUE","FALSE") -> FALSE | R12: =EXACT(G12,PROPER(G12)) -> TRUE | S12: =EXACT(H12,PROPER(H12)) -> FALSE | T12: =EXACT(I12,PROPER(I12)) -> FALSE | U12: =IF(RIGHT(J12,10)="@email.com","TRUE","FALSE") -> TRUE | V12: =IF(LEFT(K12,2)="08","TRUE","FALSE") -> TRUE
A13: 11 | B13: EMP0011 | C13: a khoirurroziqin | D13: male | E13: 1998-03-28 | F13: 2025-11-03 | G13: finance | H13: Finance Admin | I13: probation | J13: akhoirurroziqin@imail.com | K13: 085944301279 | M13: =IF(COUNTIF($B$3:$B$1002,B13)>1,"Duplicate","Ok") -> Ok | N13: =EXACT(C13,PROPER(C13)) -> FALSE | O13: =EXACT(D13,PROPER(D13)) -> FALSE | P13: =IF(ISNUMBER(E13),"TRUE","FALSE") -> FALSE | Q13: =IF(ISNUMBER(F13),"TRUE","FALSE") -> FALSE | R13: =EXACT(G13,PROPER(G13)) -> FALSE | S13: =EXACT(H13,PROPER(H13)) -> TRUE | T13: =EXACT(I13,PROPER(I13)) -> FALSE | U13: =IF(RIGHT(J13,10)="@email.com","TRUE","FALSE") -> FALSE | V13: =IF(LEFT(K13,2)="08","TRUE","FALSE") -> TRUE
A14: 12 | B14: EMP0012 | C14: dian nur ardilla | D14: male | E14: 1998-11-02 | F14: 2025-11-03 | G14: Engineering | H14: Technician | I14: active | J14: diannurardilla@imail.com | K14: 803522114 | M14: =IF(COUNTIF($B$3:$B$1002,B14)>1,"Duplicate","Ok") -> Ok | N14: =EXACT(C14,PROPER(C14)) -> FALSE | O14: =EXACT(D14,PROPER(D14)) -> FALSE | P14: =IF(ISNUMBER(E14),"TRUE","FALSE") -> FALSE | Q14: =IF(ISNUMBER(F14),"TRUE","FALSE") -> FALSE | R14: =EXACT(G14,PROPER(G14)) -> TRUE | S14: =EXACT(H14,PROPER(H14)) -> TRUE | T14: =EXACT(I14,PROPER(I14)) -> FALSE | U14: =IF(RIGHT(J14,10)="@email.com","TRUE","FALSE") -> FALSE | V14: =IF(LEFT(K14,2)="08","TRUE","FALSE") -> FALSE
A15: 13 | B15: EMP0013 | C15: lutfi ardiansyah | D15: male | E15: 2001-07-30 | F15: 2025-11-03 | G15: Production | H15: operator | I15: Probation | J15: lutfiardiansyah@email.com | K15: 87480756904 | M15: =IF(COUNTIF($B$3:$B$1002,B15)>1,"Duplicate","Ok") -> Ok | N15: =EXACT(C15,PROPER(C15)) -> FALSE | O15: =EXACT(D15,PROPER(D15)) -> FALSE | P15: =IF(ISNUMBER(E15),"TRUE","FALSE") -> FALSE | Q15: =IF(ISNUMBER(F15),"TRUE","FALSE") -> FALSE | R15: =EXACT(G15,PROPER(G15)) -> TRUE | S15: =EXACT(H15,PROPER(H15)) -> FALSE | T15: =EXACT(I15,PROPER(I15)) -> TRUE | U15: =IF(RIGHT(J15,10)="@email.com","TRUE","FALSE") -> TRUE | V15: =IF(LEFT(K15,2)="08","TRUE","FALSE") -> FALSE
A16: 14 | B16: EMP0014 | C16: rahmayanti | D16: female | E16: 2003-10-12 | F16: 2025-11-03 | G16: Production | H16: operator | I16: active | J16: rahmayanti@email.com | K16: 084798489654 | M16: =IF(COUNTIF($B$3:$B$1002,B16)>1,"Duplicate","Ok") -> Ok | N16: =EXACT(C16,PROPER(C16)) -> FALSE | O16: =EXACT(D16,PROPER(D16)) -> FALSE | P16: =IF(ISNUMBER(E16),"TRUE","FALSE") -> FALSE | Q16: =IF(ISNUMBER(F16),"TRUE","FALSE") -> FALSE | R16: =EXACT(G16,PROPER(G16)) -> TRUE | S16: =EXACT(H16,PROPER(H16)) -> FALSE | T16: =EXACT(I16,PROPER(I16)) -> FALSE | U16: =IF(RIGHT(J16,10)="@email.com","TRUE","FALSE") -> TRUE | V16: =IF(LEFT(K16,2)="08","TRUE","FALSE") -> TRUE
A17: 15 | B17: EMP0015 | C17: Rahma Yuliana | D17: female | E17: 1999-06-16 | F17: 2025-11-03 | G17: Production | H17: operator | I17: probation | J17: rahmayuliana@email.com | K17: 853887755 | M17: =IF(COUNTIF($B$3:$B$1002,B17)>1,"Duplicate","Ok") -> Ok | N17: =EXACT(C17,PROPER(C17)) -> TRUE | O17: =EXACT(D17,PROPER(D17)) -> FALSE | P17: =IF(ISNUMBER(E17),"TRUE","FALSE") -> FALSE | Q17: =IF(ISNUMBER(F17),"TRUE","FALSE") -> FALSE | R17: =EXACT(G17,PROPER(G17)) -> TRUE | S17: =EXACT(H17,PROPER(H17)) -> FALSE | T17: =EXACT(I17,PROPER(I17)) -> FALSE | U17: =IF(RIGHT(J17,10)="@email.com","TRUE","FALSE") -> TRUE | V17: =IF(LEFT(K17,2)="08","TRUE","FALSE") -> FALSE
A18: 16 | B18: EMP0016 | C18: wawan setiawan wandi | D18: Male | E18: 2004-01-02 | F18: 2025-11-03 | G18: Warehouse | H18: warehouse staff | I18: probation | J18: wawansetiawanwandi@email.com | K18: 080556387310 | M18: =IF(COUNTIF($B$3:$B$1002,B18)>1,"Duplicate","Ok") -> Ok | N18: =EXACT(C18,PROPER(C18)) -> FALSE | O18: =EXACT(D18,PROPER(D18)) -> TRUE | P18: =IF(ISNUMBER(E18),"TRUE","FALSE") -> FALSE | Q18: =IF(ISNUMBER(F18),"TRUE","FALSE") -> FALSE | R18: =EXACT(G18,PROPER(G18)) -> TRUE | S18: =EXACT(H18,PROPER(H18)) -> FALSE | T18: =EXACT(I18,PROPER(I18)) -> FALSE | U18: =IF(RIGHT(J18,10)="@email.com","TRUE","FALSE") -> TRUE | V18: =IF(LEFT(K18,2)="08","TRUE","FALSE") -> TRUE
A19: 17 | B19: EMP0017 | C19: nur aisyah | D19: female | E19: 1987-11-16 | F19: 2025-11-03 | G19: Finace | H19: Finance Admin | I19: Probation | J19: nuraisyah@email.com | K19: 085278436321 | M19: =IF(COUNTIF($B$3:$B$1002,B19)>1,"Duplicate","Ok") -> Ok | N19: =EXACT(C19,PROPER(C19)) -> FALSE | O19: =EXACT(D19,PROPER(D19)) -> FALSE | P19: =IF(ISNUMBER(E19),"TRUE","FALSE") -> FALSE | Q19: =IF(ISNUMBER(F19),"TRUE","FALSE") -> FALSE | R19: =EXACT(G19,PROPER(G19)) -> TRUE | S19: =EXACT(H19,PROPER(H19)) -> TRUE | T19: =EXACT(I19,PROPER(I19)) -> TRUE | U19: =IF(RIGHT(J19,10)="@email.com","TRUE","FALSE") -> TRUE | V19: =IF(LEFT(K19,2)="08","TRUE","FALSE") -> TRUE
A20: 18 | B20: EMP0018 | C20: Muhammad Rifal Ilyas | D20: male | E20: 1986-04-13 | F20: 2025-11-03 | G20: it | H20: it support | I20: active | J20: muhammadrifalilyas@email.com | K20: 086137380821 | M20: =IF(COUNTIF($B$3:$B$1002,B20)>1,"Duplicate","Ok") -> Ok | N20: =EXACT(C20,PROPER(C20)) -> TRUE | O20: =EXACT(D20,PROPER(D20)) -> FALSE | P20: =IF(ISNUMBER(E20),"TRUE","FALSE") -> FALSE | Q20: =IF(ISNUMBER(F20),"TRUE","FALSE") -> FALSE | R20: =EXACT(G20,PROPER(G20)) -> FALSE | S20: =EXACT(H20,PROPER(H20)) -> FALSE | T20: =EXACT(I20,PROPER(I20)) -> FALSE | U20: =IF(RIGHT(J20,10)="@email.com","TRUE","FALSE") -> TRUE | V20: =IF(LEFT(K20,2)="08","TRUE","FALSE") -> TRUE
A21: 19 | B21: EMP0019 | C21: Tiyo Aryo | D21: male | E21: 1999-07-15 | F21: 2025-11-03 | G21: Production | H21: operator | I21: probation | J21: tiyoaryo@email.com | K21: 085740892375 | M21: =IF(COUNTIF($B$3:$B$1002,B21)>1,"Duplicate","Ok") -> Ok | N21: =EXACT(C21,PROPER(C21)) -> TRUE | O21: =EXACT(D21,PROPER(D21)) -> FALSE | P21: =IF(ISNUMBER(E21),"TRUE","FALSE") -> FALSE | Q21: =IF(ISNUMBER(F21),"TRUE","FALSE") -> FALSE | R21: =EXACT(G21,PROPER(G21)) -> TRUE | S21: =EXACT(H21,PROPER(H21)) -> FALSE | T21: =EXACT(I21,PROPER(I21)) -> FALSE | U21: =IF(RIGHT(J21,10)="@email.com","TRUE","FALSE") -> TRUE | V21: =IF(LEFT(K21,2)="08","TRUE","FALSE") -> TRUE
A22: 20 | B22: EMP0020 | C22: Aditya Nugraha | D22: Male | E22: 2000-07-25 | F22: 2025-11-03 | G22: marketing | H22: marketing staff | I22: active | J22: adityanugraha@imail.com | K22: 087056427531 | M22: =IF(COUNTIF($B$3:$B$1002,B22)>1,"Duplicate","Ok") -> Ok | N22: =EXACT(C22,PROPER(C22)) -> TRUE | O22: =EXACT(D22,PROPER(D22)) -> TRUE | P22: =IF(ISNUMBER(E22),"TRUE","FALSE") -> FALSE | Q22: =IF(ISNUMBER(F22),"TRUE","FALSE") -> FALSE | R22: =EXACT(G22,PROPER(G22)) -> FALSE | S22: =EXACT(H22,PROPER(H22)) -> FALSE | T22: =EXACT(I22,PROPER(I22)) -> FALSE | U22: =IF(RIGHT(J22,10)="@email.com","TRUE","FALSE") -> FALSE | V22: =IF(LEFT(K22,2)="08","TRUE","FALSE") -> TRUE
A23: 21 | B23: EMP0021 | C23: abdul aziz | D23: male | E23: 1994-07-20 | F23: 2025-11-03 | G23: Engineering | H23: Technician | I23: ACTIVE | J23: abdulaziz@imail.com | K23: 081418040871 | M23: =IF(COUNTIF($B$3:$B$1002,B23)>1,"Duplicate","Ok") -> Ok | N23: =EXACT(C23,PROPER(C23)) -> FALSE | O23: =EXACT(D23,PROPER(D23)) -> FALSE | P23: =IF(ISNUMBER(E23),"TRUE","FALSE") -> FALSE | Q23: =IF(ISNUMBER(F23),"TRUE","FALSE") -> FALSE | R23: =EXACT(G23,PROPER(G23)) -> TRUE | S23: =EXACT(H23,PROPER(H23)) -> TRUE | T23: =EXACT(I23,PROPER(I23)) -> FALSE | U23: =IF(RIGHT(J23,10)="@email.com","TRUE","FALSE") -> FALSE | V23: =IF(LEFT(K23,2)="08","TRUE","FALSE") -> TRUE
A24: 22 | B24: EMP0022 | C24: ozi priyanto | D24: male | E24: 1987-09-27 | F24: 2025-11-03 | G24: Production | H24: operator | I24: probation | J24: ozipriyanto@email.com | K24: 087596693717 | M24: =IF(COUNTIF($B$3:$B$1002,B24)>1,"Duplicate","Ok") -> Ok | N24: =EXACT(C24,PROPER(C24)) -> FALSE | O24: =EXACT(D24,PROPER(D24)) -> FALSE | P24: =IF(ISNUMBER(E24),"TRUE","FALSE") -> FALSE | Q24: =IF(ISNUMBER(F24),"TRUE","FALSE") -> FALSE | R24: =EXACT(G24,PROPER(G24)) -> TRUE | S24: =EXACT(H24,PROPER(H24)) -> FALSE | T24: =EXACT(I24,PROPER(I24)) -> FALSE | U24: =IF(RIGHT(J24,10)="@email.com","TRUE","FALSE") -> TRUE | V24: =IF(LEFT(K24,2)="08","TRUE","FALSE") -> TRUE
A25: 23 | B25: EMP0023 | C25: M Aditya Mumin Ansori | D25: Male | E25: 1985-08-16 | F25: 2025-11-03 | G25: marketing | H25: marketing staff | I25: ACTIVE | J25: madityamuminansori@email.com | K25: 084236403700 | M25: =IF(COUNTIF($B$3:$B$1002,B25)>1,"Duplicate","Ok") -> Ok | N25: =EXACT(C25,PROPER(C25)) -> TRUE | O25: =EXACT(D25,PROPER(D25)) -> TRUE | P25: =IF(ISNUMBER(E25),"TRUE","FALSE") -> FALSE | Q25: =IF(ISNUMBER(F25),"TRUE","FALSE") -> FALSE | R25: =EXACT(G25,PROPER(G25)) -> FALSE | S25: =EXACT(H25,PROPER(H25)) -> FALSE | T25: =EXACT(I25,PROPER(I25)) -> FALSE | U25: =IF(RIGHT(J25,10)="@email.com","TRUE","FALSE") -> TRUE | V25: =IF(LEFT(K25,2)="08","TRUE","FALSE") -> TRUE
A26: 24 | B26: EMP0024 | C26: Siti Rochanah | D26: Female | E26: 1985-06-30 | F26: 2025-11-03 | G26: production | H26: operator | I26: resigned | J26: sitirochanah@email.com | K26: 089977416966 | M26: =IF(COUNTIF($B$3:$B$1002,B26)>1,"Duplicate","Ok") -> Ok | N26: =EXACT(C26,PROPER(C26)) -> TRUE | O26: =EXACT(D26,PROPER(D26)) -> TRUE | P26: =IF(ISNUMBER(E26),"TRUE","FALSE") -> FALSE | Q26: =IF(ISNUMBER(F26),"TRUE","FALSE") -> FALSE | R26: =EXACT(G26,PROPER(G26)) -> FALSE | S26: =EXACT(H26,PROPER(H26)) -> FALSE | T26: =EXACT(I26,PROPER(I26)) -> FALSE | U26: =IF(RIGHT(J26,10)="@email.com","TRUE","FALSE") -> TRUE | V26: =IF(LEFT(K26,2)="08","TRUE","FALSE") -> TRUE
A27: 25 | B27: EMP0025 | C27: miske nur agustina | D27: Male | E27: 1995-05-03 | F27: 2025-11-03 | G27: warehouse | H27: Warehouse Staff | I27: Resigned | J27: miskenuragustina@email.com | K27: 085419858274 | M27: =IF(COUNTIF($B$3:$B$1002,B27)>1,"Duplicate","Ok") -> Ok | N27: =EXACT(C27,PROPER(C27)) -> FALSE | O27: =EXACT(D27,PROPER(D27)) -> TRUE | P27: =IF(ISNUMBER(E27),"TRUE","FALSE") -> FALSE | Q27: =IF(ISNUMBER(F27),"TRUE","FALSE") -> FALSE | R27: =EXACT(G27,PROPER(G27)) -> FALSE | S27: =EXACT(H27,PROPER(H27)) -> TRUE | T27: =EXACT(I27,PROPER(I27)) -> TRUE | U27: =IF(RIGHT(J27,10)="@email.com","TRUE","FALSE") -> TRUE | V27: =IF(LEFT(K27,2)="08","TRUE","FALSE") -> TRUE
A28: 26 | B28: EMP0026 | C28: Novi Wulandari | D28: female | E28: 1985-03-02 | F28: 2025-11-03 | G28: Prodction | H28: Operator | I28: probation | J28: noviwulandari@email.com | K28: 084291820015 | M28: =IF(COUNTIF($B$3:$B$1002,B28)>1,"Duplicate","Ok") -> Ok | N28: =EXACT(C28,PROPER(C28)) -> TRUE | O28: =EXACT(D28,PROPER(D28)) -> FALSE | P28: =IF(ISNUMBER(E28),"TRUE","FALSE") -> FALSE | Q28: =IF(ISNUMBER(F28),"TRUE","FALSE") -> FALSE | R28: =EXACT(G28,PROPER(G28)) -> TRUE | S28: =EXACT(H28,PROPER(H28)) -> TRUE | T28: =EXACT(I28,PROPER(I28)) -> FALSE | U28: =IF(RIGHT(J28,10)="@email.com","TRUE","FALSE") -> TRUE | V28: =IF(LEFT(K28,2)="08","TRUE","FALSE") -> TRUE
A29: 27 | B29: EMP0027 | C29: rohmat | D29: male | E29: 1994-02-13 | F29: 2025-11-03 | G29: Production | H29: operator | I29: Probation | J29: rohmat@email.com | K29: 085701851280 | M29: =IF(COUNTIF($B$3:$B$1002,B29)>1,"Duplicate","Ok") -> Ok | N29: =EXACT(C29,PROPER(C29)) -> FALSE | O29: =EXACT(D29,PROPER(D29)) -> FALSE | P29: =IF(ISNUMBER(E29),"TRUE","FALSE") -> FALSE | Q29: =IF(ISNUMBER(F29),"TRUE","FALSE") -> FALSE | R29: =EXACT(G29,PROPER(G29)) -> TRUE | S29: =EXACT(H29,PROPER(H29)) -> FALSE | T29: =EXACT(I29,PROPER(I29)) -> TRUE | U29: =IF(RIGHT(J29,10)="@email.com","TRUE","FALSE") -> TRUE | V29: =IF(LEFT(K29,2)="08","TRUE","FALSE") -> TRUE
... A39: 37 | B39: EMP0037 | C39: Rizqi Amalia | D39: Female | E39: 1989-11-04 | F39: 2025-11-03 | G39: production | H39: operator | I39: Resigned | J39: rizqiamalia@email.com | K39: 086508782132 | M39: =IF(COUNTIF($B$3:$B$1002,B39)>1,"Duplicate","Ok") -> Ok | N39: =EXACT(C39,PROPER(C39)) -> TRUE | O39: =EXACT(D39,PROPER(D39)) -> TRUE | P39: =IF(ISNUMBER(E39),"TRUE","FALSE") -> FALSE | Q39: =IF(ISNUMBER(F39),"TRUE","FALSE") -> FALSE | R39: =EXACT(G39,PROPER(G39)) -> FALSE | S39: =EXACT(H39,PROPER(H39)) -> FALSE | T39: =EXACT(I39,PROPER(I39)) -> TRUE | U39: =IF(RIGHT(J39,10)="@email.com","TRUE","FALSE") -> TRUE | V39: =IF(LEFT(K39,2)="08","TRUE","FALSE") -> TRUE
A40: 38 | B40: EMP0038 | C40: Beni | D40: Male | E40: 2001-03-09 | F40: 2025-11-03 | G40: Prodction | H40: Operator | I40: ACTIVE | J40: beni@imail.com | K40: 846922616 | M40: =IF(COUNTIF($B$3:$B$1002,B40)>1,"Duplicate","Ok") -> Ok | N40: =EXACT(C40,PROPER(C40)) -> TRUE | O40: =EXACT(D40,PROPER(D40)) -> TRUE | P40: =IF(ISNUMBER(E40),"TRUE","FALSE") -> FALSE | Q40: =IF(ISNUMBER(F40),"TRUE","FALSE") -> FALSE | R40: =EXACT(G40,PROPER(G40)) -> TRUE | S40: =EXACT(H40,PROPER(H40)) -> TRUE | T40: =EXACT(I40,PROPER(I40)) -> FALSE | U40: =IF(RIGHT(J40,10)="@email.com","TRUE","FALSE") -> FALSE | V40: =IF(LEFT(K40,2)="08","TRUE","FALSE") -> FALSE
A41: 39 | B41: EMP0039 | C41: Vitriya Amanda Putri | D41: female | E41: 2004-01-25 | F41: 2025-11-03 | G41: hr | H41: hr staff | I41: ACTIVE | J41: vitriyaamandaputri@email.com | K41: 086460584576 | M41: =IF(COUNTIF($B$3:$B$1002,B41)>1,"Duplicate","Ok") -> Ok | N41: =EXACT(C41,PROPER(C41)) -> TRUE | O41: =EXACT(D41,PROPER(D41)) -> FALSE | P41: =IF(ISNUMBER(E41),"TRUE","FALSE") -> FALSE | Q41: =IF(ISNUMBER(F41),"TRUE","FALSE") -> FALSE | R41: =EXACT(G41,PROPER(G41)) -> FALSE | S41: =EXACT(H41,PROPER(H41)) -> FALSE | T41: =EXACT(I41,PROPER(I41)) -> FALSE | U41: =IF(RIGHT(J41,10)="@email.com","TRUE","FALSE") -> TRUE | V41: =IF(LEFT(K41,2)="08","TRUE","FALSE") -> TRUE
A42: 40 | B42: EMP0040 | C42: Alda Surya Wijaya | D42: Male | E42: 1988-01-26 | F42: 2025-11-03 | G42: production | H42: operator | I42: resigned | J42: aldasuryawijaya@imail.com | K42: 088873927718 | M42: =IF(COUNTIF($B$3:$B$1002,B42)>1,"Duplicate","Ok") -> Ok | N42: =EXACT(C42,PROPER(C42)) -> TRUE | O42: =EXACT(D42,PROPER(D42)) -> TRUE | P42: =IF(ISNUMBER(E42),"TRUE","FALSE") -> FALSE | Q42: =IF(ISNUMBER(F42),"TRUE","FALSE") -> FALSE | R42: =EXACT(G42,PROPER(G42)) -> FALSE | S42: =EXACT(H42,PROPER(H42)) -> FALSE | T42: =EXACT(I42,PROPER(I42)) -> FALSE | U42: =IF(RIGHT(J42,10)="@email.com","TRUE","FALSE") -> FALSE | V42: =IF(LEFT(K42,2)="08","TRUE","FALSE") -> TRUE
A43: 41 | B43: EMP0041 | C43: Fika Suci Sanawaliyah | D43: female | E43: 1987-11-24 | F43: 2025-11-03 | G43: Production | H43: operator | I43: Probation | J43: fikasucisanawaliyah@imail.com | K43: 85636332286 | M43: =IF(COUNTIF($B$3:$B$1002,B43)>1,"Duplicate","Ok") -> Ok | N43: =EXACT(C43,PROPER(C43)) -> TRUE | O43: =EXACT(D43,PROPER(D43)) -> FALSE | P43: =IF(ISNUMBER(E43),"TRUE","FALSE") -> FALSE | Q43: =IF(ISNUMBER(F43),"TRUE","FALSE") -> FALSE | R43: =EXACT(G43,PROPER(G43)) -> TRUE | S43: =EXACT(H43,PROPER(H43)) -> FALSE | T43: =EXACT(I43,PROPER(I43)) -> TRUE | U43: =IF(RIGHT(J43,10)="@email.com","TRUE","FALSE") -> FALSE | V43: =IF(LEFT(K43,2)="08","TRUE","FALSE") -> FALSE
A44: 42 | B44: EMP0042 | C44: Bagus Wiranto | D44: Male | E44: 1990-05-01 | F44: 2025-11-03 | G44: purchasing | H44: Purchasing Staff | I44: active | J44: baguswiranto@imail.com | K44: 082626918134 | M44: =IF(COUNTIF($B$3:$B$1002,B44)>1,"Duplicate","Ok") -> Ok | N44: =EXACT(C44,PROPER(C44)) -> TRUE | O44: =EXACT(D44,PROPER(D44)) -> TRUE | P44: =IF(ISNUMBER(E44),"TRUE","FALSE") -> FALSE | Q44: =IF(ISNUMBER(F44),"TRUE","FALSE") -> FALSE | R44: =EXACT(G44,PROPER(G44)) -> FALSE | S44: =EXACT(H44,PROPER(H44)) -> TRUE | T44: =EXACT(I44,PROPER(I44)) -> FALSE | U44: =IF(RIGHT(J44,10)="@email.com","TRUE","FALSE") -> FALSE | V44: =IF(LEFT(K44,2)="08","TRUE","FALSE") -> TRUE
A45: 43 | B45: EMP0043 | C45: Sahrul Faizal Ramadhon | D45: Male | E45: 1990-01-10 | F45: 2025-11-03 | G45: Production | H45: operator | I45: Active | J45: sahrulfaizalramadhon@email.com | K45: 084739492257 | M45: =IF(COUNTIF($B$3:$B$1002,B45)>1,"Duplicate","Ok") -> Ok | N45: =EXACT(C45,PROPER(C45)) -> TRUE | O45: =EXACT(D45,PROPER(D45)) -> TRUE | P45: =IF(ISNUMBER(E45),"TRUE","FALSE") -> FALSE | Q45: =IF(ISNUMBER(F45),"TRUE","FALSE") -> FALSE | R45: =EXACT(G45,PROPER(G45)) -> TRUE | S45: =EXACT(H45,PROPER(H45)) -> FALSE | T45: =EXACT(I45,PROPER(I45)) -> TRUE | U45: =IF(RIGHT(J45,10)="@email.com","TRUE","FALSE") -> TRUE | V45: =IF(LEFT(K45,2)="08","TRUE","FALSE") -> TRUE
A46: 44 | B46: EMP0044 | C46: Dian Prastiana | D46: male | E46: 1987-01-08 | F46: 2025-11-03 | G46: prodution | H46: operator | I46: Probation | J46: dianprastiana@imail.com | K46: 086451989393 | M46: =IF(COUNTIF($B$3:$B$1002,B46)>1,"Duplicate","Ok") -> Ok | N46: =EXACT(C46,PROPER(C46)) -> TRUE | O46: =EXACT(D46,PROPER(D46)) -> FALSE | P46: =IF(ISNUMBER(E46),"TRUE","FALSE") -> FALSE | Q46: =IF(ISNUMBER(F46),"TRUE","FALSE") -> FALSE | R46: =EXACT(G46,PROPER(G46)) -> FALSE | S46: =EXACT(H46,PROPER(H46)) -> FALSE | T46: =EXACT(I46,PROPER(I46)) -> TRUE | U46: =IF(RIGHT(J46,10)="@email.com","TRUE","FALSE") -> FALSE | V46: =IF(LEFT(K46,2)="08","TRUE","FALSE") -> TRUE
A47: 45 | B47: EMP0045 | C47: Uswatun Khasanah | D47: Female | E47: 1989-12-22 | F47: 2025-11-03 | G47: production | H47: Operator | I47: active | J47: uswatunkhasanah@email.com | K47: 084176066224 | M47: =IF(COUNTIF($B$3:$B$1002,B47)>1,"Duplicate","Ok") -> Ok | N47: =EXACT(C47,PROPER(C47)) -> TRUE | O47: =EXACT(D47,PROPER(D47)) -> TRUE | P47: =IF(ISNUMBER(E47),"TRUE","FALSE") -> FALSE | Q47: =IF(ISNUMBER(F47),"TRUE","FALSE") -> FALSE | R47: =EXACT(G47,PROPER(G47)) -> FALSE | S47: =EXACT(H47,PROPER(H47)) -> TRUE | T47: =EXACT(I47,PROPER(I47)) -> FALSE | U47: =IF(RIGHT(J47,10)="@email.com","TRUE","FALSE") -> TRUE | V47: =IF(LEFT(K47,2)="08","TRUE","FALSE") -> TRUE
A48: 46 | B48: EMP0046 | C48: Ika Risyifa Khaerunissa | D48: female | E48: 1996-10-18 | F48: 2025-11-03 | G48: Production | H48: operator | I48: active | J48: ikarisyifakhaerunissa@email.com | K48: 082084751572 | M48: =IF(COUNTIF($B$3:$B$1002,B48)>1,"Duplicate","Ok") -> Ok | N48: =EXACT(C48,PROPER(C48)) -> TRUE | O48: =EXACT(D48,PROPER(D48)) -> FALSE | P48: =IF(ISNUMBER(E48),"TRUE","FALSE") -> FALSE | Q48: =IF(ISNUMBER(F48),"TRUE","FALSE") -> FALSE | R48: =EXACT(G48,PROPER(G48)) -> TRUE | S48: =EXACT(H48,PROPER(H48)) -> FALSE | T48: =EXACT(I48,PROPER(I48)) -> FALSE | U48: =IF(RIGHT(J48,10)="@email.com","TRUE","FALSE") -> TRUE | V48: =IF(LEFT(K48,2)="08","TRUE","FALSE") -> TRUE
A49: 47 | B49: EMP0047 | C49: Ayu Pratmawati | D49: Female | E49: 1993-10-06 | F49: 2025-11-03 | G49: production | H49: Operator | I49: probation | J49: ayupratmawati@imail.com | K49: 086743969318 | M49: =IF(COUNTIF($B$3:$B$1002,B49)>1,"Duplicate","Ok") -> Ok | N49: =EXACT(C49,PROPER(C49)) -> TRUE | O49: =EXACT(D49,PROPER(D49)) -> TRUE | P49: =IF(ISNUMBER(E49),"TRUE","FALSE") -> FALSE | Q49: =IF(ISNUMBER(F49),"TRUE","FALSE") -> FALSE | R49: =EXACT(G49,PROPER(G49)) -> FALSE | S49: =EXACT(H49,PROPER(H49)) -> TRUE | T49: =EXACT(I49,PROPER(I49)) -> FALSE | U49: =IF(RIGHT(J49,10)="@email.com","TRUE","FALSE") -> FALSE | V49: =IF(LEFT(K49,2)="08","TRUE","FALSE") -> TRUE
...

Sheet Clean Data
A1: Employee Master Database Management
A2: No | B2: Employee ID | C2: Full Name | D2: Gender | E2: DOB | F2: Join Date | G2: Department | H2: Position | I2: Status | J2: Email | K2: Phone
A3: 1 | B3: EMP0001 | C3: Ridwan Akmaluddin | D3: Male | E3: 32288 | F3: 45964 | G3: Production | H3: Operator | I3: Active | J3: ridwanakmaluddin@email.com | K3: 082188191195
A4: 2 | B4: EMP0002 | C4: Siti Maghfiroh | D4: Female | E4: 31687 | F4: 45964 | G4: Production | H4: Operator | I4: Active | J4: sitimaghfiroh@email.com | K4: 0893260231
A5: 3 | B5: EMP0003 | C5: Diyah Rhodhotul Avivah | D5: Female | E5: 34609 | F5: 45964 | G5: QC | H5: QC Inspector | I5: Resigned | J5: diyahrhodhotulavivah@email.com | K5: 088550888361
A6: 4 | B6: EMP0004 | C6: Avielva Zhelviany | D6: Female | E6: 37745 | F6: 45964 | G6: Purchasing | H6: Purchasing Staff | I6: Active | J6: avielvazhelviany@email.com | K6: 085713227015
A7: 5 | B7: EMP0005 | C7: Dede Mulyaningsih | D7: Female | E7: 35757 | F7: 45964 | G7: Production | H7: Operator | I7: Active | J7: dedemulyaningsih@email.com | K7: 080015675393
A8: 6 | B8: EMP0006 | C8: Ferri Riyanto | D8: Male | E8: 37423 | F8: 45964 | G8: Production | H8: Operator | I8: Probation | J8: ferririyanto@email.com | K8: 082274087008
A9: 7 | B9: EMP0007 | C9: Alfi Nur Fadilah | D9: Female | E9: 31710 | F9: 45964 | G9: QC | H9: QC Inspector | I9: Active | J9: alfinurfadilah@email.com | K9: 083226933728
A10: 8 | B10: EMP0008 | C10: Latif Ainur Rokhmah | D10: Female | E10: 32421 | F10: 45964 | G10: Purchasing | H10: Purchasing Staff | I10: Active | J10: latifainurrokhmah@email.com | K10: 087585339477
A11: 9 | B11: EMP0009 | C11: Fajar B Pratama | D11: Male | E11: 34269 | F11: 45964 | G11: Production | H11: Operator | I11: Probation | J11: fajarbpratama@email.com | K11: 089883379308
A12: 10 | B12: EMP0010 | C12: Veby Astriani | D12: Female | E12: 32216 | F12: 45964 | G12: Production | H12: Operator | I12: Resigned | J12: vebyastriani@email.com | K12: 085418191103
A13: 11 | B13: EMP0011 | C13: A Khoirurroziqin | D13: Male | E13: 35882 | F13: 45964 | G13: Finance | H13: Finance Admin | I13: Probation | J13: akhoirurroziqin@email.com | K13: 085944301279
A14: 12 | B14: EMP0012 | C14: Dian Nur Ardilla | D14: Male | E14: 36101 | F14: 45964 | G14: Engineering | H14: Technician | I14: Active | J14: diannurardilla@email.com | K14: 0803522114
... A1002: 1000 | B1002: EMP1000 | C1002: Agus Priyadi | D1002: Male | E1002: 32340 | F1002: 46147 | G1002: Warehouse | H1002: Warehouse Staff | I1002: Active | J1002: aguspriyadi@email.com | K1002: 080019026420

Sheet Data Validation Summary
A1: Data Standards
A2: No | B2: Category | C2: Rule | D2: Ok | E2: Issue Found | F2: Total | G2: Status | H2: Excel Function Used
A3: 1 | B3: Employee ID | C3: Must be unique | D3: =COUNTIF('Working Copy & Validation Check'!$M$3:$M$1002,"Ok") -> 1000 | E3: =COUNTIF('Working Copy & Validation Check'!$M$3:$M$1002,"Duplicate") -> 0 | F3: =+D3+E3 -> 1000 | G3: Fixed | H3: =IF(COUNTIF($B$3:$B$1002,B3)>1,"Duplicate","Ok")
A4: 2 | B4: Full Name | C4: Proper Case | D4: =COUNTIF('Working Copy & Validation Check'!$N$3:$N$1002,"TRUE") -> 502 | E4: =COUNTIF('Working Copy & Validation Check'!$N$3:$N$1002,"FALSE") -> 498 | F4: =+D4+E4 -> 1000 | G4: Fixed | H4: =EXACT(C3,PROPER(C3))
A5: 3 | B5: Gender | C5: Male/Female only | D5: =COUNTIF('Working Copy & Validation Check'!$O$3:$O$1002,"TRUE") -> 472 | E5: =COUNTIF('Working Copy & Validation Check'!$O$3:$O$1002,"FALSE") -> 528 | F5: =+D5+E5 -> 1000 | G5: Fixed | H5: =EXACT(D3,PROPER(D3))
A6: 4 | B6: DOB | C6: Valid date | D6: =COUNTIFS('Working Copy & Validation Check'!$P$3:$P$1002,"TRUE") -> 0 | E6: 1000 | F6: =+D6+E6 -> 1000 | G6: Fixed | H6: =IF(ISNUMBER(E3),"TRUE","FALSE")
A7: 5 | B7: Join Date | C7: Valid date | D7: =COUNTIF('Working Copy & Validation Check'!$Q$3:$Q$1002,TRUE) -> 0 | E7: 1000 | F7: =+D7+E7 -> 1000 | G7: Fixed | H7: =IF(ISNUMBER(F3),"TRUE","FALSE")
A8: 6 | B8: Department | C8: Proper Case | D8: =COUNTIF('Working Copy & Validation Check'!$R$3:$R$1002,"TRUE") -> 476 | E8: =COUNTIF('Working Copy & Validation Check'!$R$3:$R$1002,"FALSE") -> 524 | F8: =+D8+E8 -> 1000 | G8: Fixed | H8: =EXACT(G3,PROPER(G3))
A9: 7 | B9: Position | C9: Proper Case | D9: =COUNTIF('Working Copy & Validation Check'!$S$3:$S$1002,"TRUE") -> 265 | E9: =COUNTIF('Working Copy & Validation Check'!$S$3:$S$1002,"FALSE") -> 735 | F9: =+D9+E9 -> 1000 | G9: Fixed | H9: =EXACT(H3,PROPER(H3))
A10: 8 | B10: Status | C10: Proper Case | D10: =COUNTIF('Working Copy & Validation Check'!$T$3:$T$1002,"TRUE") -> 400 | E10: =COUNTIF('Working Copy & Validation Check'!$T$3:$T$1002,"FALSE") -> 600 | F10: =+D10+E10 -> 1000 | G10: Fixed | H10: =EXACT(I3,PROPER(I3))
A11: 9 | B11: Email | C11: Valid email format | D11: 681 | E11: 319 | F11: =+D11+E11 -> 1000 | G11: Fixed | H11: =IF(RIGHT(J3,10)="@email.com","TRUE","FALSE")
A12: 10 | B12: Phone | C12: Numeric only, starts with 08 | D12: 819 | E12: 181 | F12: =+D12+E12 -> 1000 | G12: Fixed | H12: =IF(LEFT(K3,2)="08","TRUE","FALSE")
A15: Validation Rules
A16: No | B16: Field | C16: Validation Rule
A17: 1 | B17: Employee ID | C17: Must be unique
A18: 2 | B18: Full Name | C18: Proper Case
A19: 3 | B19: Gender | C19: Male or Female only
A20: 4 | B20: DOB | C20: Valid date format (DD-MM-YYYY)
A21: 5 | B21: Join Date | C21: Valid date format (DD-MM-YYYY)
A22: 6 | B22: Department | C22: HR, Finance, IT, Production, Warehouse, Marketing, QC , Purchasing, Engineering
A23: 7 | B23: Position | C23: Match Position Master
A24: 8 | B24: Status | C24: Active, Probation, Resigned
A25: 9 | B25: Email | C25: Must contain "@email.com"
A26: 10 | B26: Phone | C26: Numeric only

Sheet Data Cleaning Guide
A2: Data Cleaning Guide
A3: This guide describes the data cleaning procedures used to standardize and improve the quality of the Employee Master dataset.
A5: Data field | B5: Cleaning Procedure
A6: 1. Full Name and Gender | B6: Use the PROPER function to convert all text into Proper Case.
A7: 2. Date of Birth (DOB) and Join Date | B7: Convert the text to a valid Excel date by following these steps:
B8: Go to Data → Text to Columns.
B9: Select Delimited → Next.
B10: Leave all delimiters unchecked, then click Next.
B11: Under Column Data Format, select Date (YMD).
B12: Click Finish.
B14: To display the date in the required format:
B15: Go to Home → Number Format → Custom.
B16: Enter DD-MM-YYYY, then click OK.
A18: 3. Department | B18: Apply a filter to identify incorrect department names.
B19: Correct any misspelled department names.
B20: Use the PROPER function to standardize the text.
B21: For abbreviations such as HR, IT, and QC, use the UPPER function.
A23: 4. Position | B23: Use the Find and Replace tool to correct misspelled position names.
B24: Find what: Enter the incorrect text.
B25: Replace with: Enter the correct text.
B26: Alternatively, use the PROPER function together with SUBSTITUTE to preserve abbreviations.
B28: Example:
B29: =SUBSTITUTE(PROPER(A2),"Hr ","HR ")
B30: This example is specifically for the abbreviation HR.
A32: 5. Status | B32: Use the PROPER function to standardize all status values.
A34: 6. Email | B34: Use the Find and Replace tool to correct invalid email domains.
B36: Example:
B37: Find what: @imail.com
B38: Replace with: @email.com
A40: 7. Phone Number | B40: Apply a filter to identify invalid phone numbers.
B41: If a phone number is missing the leading zero, use the following formula:
B43: ="0"&A2
B44: Replace A2 with the appropriate cell reference.

Sheet Data Dictionary
A1: Title | B1: Data Dictionary
A2: Description | B2: This document describes the structure, data types, and definitions of each column in the Employee Master dataset.
A4: Column Name | B4: Data Type | C4: Description | D4: Example
A5: Employee ID | B5: Text | C5: Unique identifier assigned to each employee. | D5: EMP0001
A6: Full Name | B6: Text | C6: Employee's full name. | D6: John Smith
A7: Gender | B7: Text | C7: Employee's gender. | D7: Female
A8: Date of Birth | B8: Date | C8: Employee's date of birth. | D8: 15-08-1995
A9: Join Date | B9: Date | C9: Employee's employment start date. | D9: 01-02-2024
A10: Department | B10: Text | C10: Employee's department. | D10: HR
A11: Position | B11: Text | C11: Employee's job title. | D11: HR Staff
A12: Status | B12: Text | C12: Employee's employment status. | D12: Active
A13: Email | B13: Text | C13: Employee's email address. | D13: john@email.com
A14: Phone Number | B14: Text | C14: Employee's contact number. | D14: 081234567890

Sheet Dashboard
A1: Employee Master Dashboard
B4: Total Employees | D4: Total Departments | F4: Total Positions
B5: 1000 | D5: =COUNT($B$24:$B$32) -> 9 | F5: =COUNT($K$24:$K$32) -> 9
A10: Row Labels | B10: Count of Status | G10: Row Labels | H10: Count of Gender
A11: Active | B11: 464 | G11: Female | H11: 597
A12: Probation | B12: 300 | G12: Male | H12: 403
A13: Resigned | B13: 236 | G13: Grand Total | H13: 1000
A14: Grand Total | B14: 1000
A23: Row Labels | B23: Count of Department | J23: Row Labels | K23: Count of Position
A24: Engineering | B24: 68 | J24: Finance Admin | K24: 18
A25: Finance | B25: 18 | J25: HR Staff | K25: 18
A26: HR | B26: 18 | J26: IT Support | K26: 32
A27: IT | B27: 32 | J27: Marketing Staff | K27: 15
A28: Marketing | B28: 15 | J28: Operator | K28: 638
A29: Production | B29: 638 | J29: Purchasing Staff | K29: 12
A30: Purchasing | B30: 12 | J30: QC Inspector | K30: 102
A31: QC | B31: 102 | J31: Technician | K31: 68
A32: Warehouse | B32: 97 | J32: Warehouse Staff | K32: 97
A33: Grand Total | B33: 1000 | J33: Grand Total | K33: 1000
